Workbook

Sheet Config
A1: Configuration Panel - Edit yellow cells to recalculate the entire workbook
A2: Change the yellow cells. All heatmap and shrinkage calculations update automatically.
A5: Named Cell | B5: Parameter | C5: Value | D5: Unit | E5: Notes
A6: AHT | B6: AHT (Average Handle Time) | C6: 16 | D6: minutes | E6: Average time per chat in minutes
A7: CONC | B7: Concurrency | C7: 3 | D7: chats | E7: Simultaneous chats per agent. Typical: 2.5-4.0
A8: SLOT_MINS | B8: Slot Size | C8: 30 | D8: minutes | E8: Heatmap granularity (30 min recommended)
A9: ROSTER | B9: Rostered Headcount | C9: 39 | D9: agents | E9: Total agents on roster
A10: UNPLN_PCT | B10: Unplanned Shrinkage % | C10: 0.1 | E10: Sick calls / no-shows. Benchmark: 8-12%
A12: DERIVED VALUES (auto-calculated - do not edit)
A13: Effective Roster | C13: =Config!C9*(1-Config!C10)
A14: Shrinkage Ratio | C14: =1-Config!C10
A15: Formula note | C15: =(Avg Chats x AHT) / Slot_mins / Concurrency
A17: TIP: Change AHT or Concurrency above, press Enter, and Agents Needed updates across all sheets

Sheet Half-Hour Heatmap
A1: Chat Volume Heatmap | 30-Min Slots | 2026-04-06 to 2026-04-15 | Edit AHT & Concurrency in Config sheet
A3: Slot | B3: Mon | C3: Tue | D3: Wed | E3: Thu | F3: Fri | G3: Sat | H3: Sun | I3: Daily Avg | J3: Agents Needed | K3: Online (Shift) | L3: Gap (+/-) | M3: Status | N3: Shift Window
A4: 00:00 | B4: 102 | C4: 124 | D4: 114 | E4: 75 | F4: 104 | G4: 85 | H4: 92 | I4: 99 | J4: =ROUND(I4*Config!C6/Config!C8/Config!C7,1) | K4: 16 | L4: =ROUND(K4-J4,1) | M4: =IF(L4>=3,"Comfortable",IF(L4>=1,"Good",IF(L4>=0,"Tight",IF(L4>=-2,"Under","Critical")))) | N4: S3+S4
A5: 00:30 | B5: 80 | C5: 114 | D5: 121 | E5: 93 | F5: 99 | G5: 70 | H5: 92 | I5: 96 | J5: =ROUND(I5*Config!C6/Config!C8/Config!C7,1) | K5: 16 | L5: =ROUND(K5-J5,1) | M5: =IF(L5>=3,"Comfortable",IF(L5>=1,"Good",IF(L5>=0,"Tight",IF(L5>=-2,"Under","Critical")))) | N5: S3+S4
A6: 01:00 | B6: 88 | C6: 102 | D6: 112 | E6: 69 | F6: 80 | G6: 56 | H6: 87 | I6: 85 | J6: =ROUND(I6*Config!C6/Config!C8/Config!C7,1) | K6: 16 | L6: =ROUND(K6-J6,1) | M6: =IF(L6>=3,"Comfortable",IF(L6>=1,"Good",IF(L6>=0,"Tight",IF(L6>=-2,"Under","Critical")))) | N6: S3+S4
A7: 01:30 | B7: 82 | C7: 110 | D7: 80 | E7: 91 | F7: 92 | G7: 55 | H7: 87 | I7: 85 | J7: =ROUND(I7*Config!C6/Config!C8/Config!C7,1) | K7: 16 | L7: =ROUND(K7-J7,1) | M7: =IF(L7>=3,"Comfortable",IF(L7>=1,"Good",IF(L7>=0,"Tight",IF(L7>=-2,"Under","Critical")))) | N7: S3+S4
A8: 02:00 | B8: 78 | C8: 92 | D8: 92 | E8: 84 | F8: 84 | G8: 66 | H8: 60 | I8: 79 | J8: =ROUND(I8*Config!C6/Config!C8/Config!C7,1) | K8: 16 | L8: =ROUND(K8-J8,1) | M8: =IF(L8>=3,"Comfortable",IF(L8>=1,"Good",IF(L8>=0,"Tight",IF(L8>=-2,"Under","Critical")))) | N8: S3+S4
A9: 02:30 | B9: 62 | C9: 88 | D9: 98 | E9: 99 | F9: 80 | G9: 50 | H9: 70 | I9: 78 | J9: =ROUND(I9*Config!C6/Config!C8/Config!C7,1) | K9: 16 | L9: =ROUND(K9-J9,1) | M9: =IF(L9>=3,"Comfortable",IF(L9>=1,"Good",IF(L9>=0,"Tight",IF(L9>=-2,"Under","Critical")))) | N9: S3+S4
A10: 03:00 | B10: 72 | C10: 100 | D10: 102 | E10: 70 | F10: 59 | G10: 46 | H10: 55 | I10: 72 | J10: =ROUND(I10*Config!C6/Config!C8/Config!C7,1) | K10: 6 | L10: =ROUND(K10-J10,1) | M10: =IF(L10>=3,"Comfortable",IF(L10>=1,"Good",IF(L10>=0,"Tight",IF(L10>=-2,"Under","Critical")))) | N10: S4
A11: 03:30 | B11: 74 | C11: 94 | D11: 90 | E11: 93 | F11: 80 | G11: 52 | H11: 67 | I11: 79 | J11: =ROUND(I11*Config!C6/Config!C8/Config!C7,1) | K11: 6 | L11: =ROUND(K11-J11,1) | M11: =IF(L11>=3,"Comfortable",IF(L11>=1,"Good",IF(L11>=0,"Tight",IF(L11>=-2,"Under","Critical")))) | N11: S4
A12: 04:00 | B12: 68 | C12: 80 | D12: 63 | E12: 74 | F12: 65 | G12: 54 | H12: 37 | I12: 63 | J12: =ROUND(I12*Config!C6/Config!C8/Config!C7,1) | K12: 6 | L12: =ROUND(K12-J12,1) | M12: =IF(L12>=3,"Comfortable",IF(L12>=1,"Good",IF(L12>=0,"Tight",IF(L12>=-2,"Under","Critical")))) | N12: S4
A13: 04:30 | B13: 74 | C13: 77 | D13: 62 | E13: 57 | F13: 57 | G13: 46 | H13: 68 | I13: 63 | J13: =ROUND(I13*Config!C6/Config!C8/Config!C7,1) | K13: 6 | L13: =ROUND(K13-J13,1) | M13: =IF(L13>=3,"Comfortable",IF(L13>=1,"Good",IF(L13>=0,"Tight",IF(L13>=-2,"Under","Critical")))) | N13: S4
A14: 05:00 | B14: 62 | C14: 71 | D14: 78 | E14: 43 | F14: 50 | G14: 29 | H14: 78 | I14: 59 | J14: =ROUND(I14*Config!C6/Config!C8/Config!C7,1) | K14: 6 | L14: =ROUND(K14-J14,1) | M14: =IF(L14>=3,"Comfortable",IF(L14>=1,"Good",IF(L14>=0,"Tight",IF(L14>=-2,"Under","Critical")))) | N14: S4
A15: 05:30 | B15: 64 | C15: 80 | D15: 78 | E15: 65 | F15: 74 | G15: 37 | H15: 50 | I15: 64 | J15: =ROUND(I15*Config!C6/Config!C8/Config!C7,1) | K15: 6 | L15: =ROUND(K15-J15,1) | M15: =IF(L15>=3,"Comfortable",IF(L15>=1,"Good",IF(L15>=0,"Tight",IF(L15>=-2,"Under","Critical")))) | N15: S4
A16: 06:00 | B16: 65 | C16: 86 | D16: 71 | E16: 62 | F16: 64 | G16: 35 | H16: 70 | I16: 65 | J16: =ROUND(I16*Config!C6/Config!C8/Config!C7,1) | K16: 6 | L16: =ROUND(K16-J16,1) | M16: =IF(L16>=3,"Comfortable",IF(L16>=1,"Good",IF(L16>=0,"Tight",IF(L16>=-2,"Under","Critical")))) | N16: S4
A17: 06:30 | B17: 74 | C17: 67 | D17: 72 | E17: 114 | F17: 76 | G17: 41 | H17: 74 | I17: 74 | J17: =ROUND(I17*Config!C6/Config!C8/Config!C7,1) | K17: 6 | L17: =ROUND(K17-J17,1) | M17: =IF(L17>=3,"Comfortable",IF(L17>=1,"Good",IF(L17>=0,"Tight",IF(L17>=-2,"Under","Critical")))) | N17: S4
A18: 07:00 | B18: 80 | C18: 68 | D18: 71 | E18: 80 | F18: 75 | G18: 50 | H18: 45 | I18: 67 | J18: =ROUND(I18*Config!C6/Config!C8/Config!C7,1) | K18: 19 | L18: =ROUND(K18-J18,1) | M18: =IF(L18>=3,"Comfortable",IF(L18>=1,"Good",IF(L18>=0,"Tight",IF(L18>=-2,"Under","Critical")))) | N18: S1+S4
A19: 07:30 | B19: 70 | C19: 76 | D19: 69 | E19: 82 | F19: 90 | G19: 60 | H19: 56 | I19: 72 | J19: =ROUND(I19*Config!C6/Config!C8/Config!C7,1) | K19: 19 | L19: =ROUND(K19-J19,1) | M19: =IF(L19>=3,"Comfortable",IF(L19>=1,"Good",IF(L19>=0,"Tight",IF(L19>=-2,"Under","Critical")))) | N19: S1+S4
A20: 08:00 | B20: 76 | C20: 86 | D20: 82 | E20: 73 | F20: 91 | G20: 53 | H20: 67 | I20: 75 | J20: =ROUND(I20*Config!C6/Config!C8/Config!C7,1) | K20: 13 | L20: =ROUND(K20-J20,1) | M20: =IF(L20>=3,"Comfortable",IF(L20>=1,"Good",IF(L20>=0,"Tight",IF(L20>=-2,"Under","Critical")))) | N20: S1
A21: 08:30 | B21: 78 | C21: 76 | D21: 70 | E21: 92 | F21: 56 | G21: 47 | H21: 66 | I21: 69 | J21: =ROUND(I21*Config!C6/Config!C8/Config!C7,1) | K21: 13 | L21: =ROUND(K21-J21,1) | M21: =IF(L21>=3,"Comfortable",IF(L21>=1,"Good",IF(L21>=0,"Tight",IF(L21>=-2,"Under","Critical")))) | N21: S1
A22: 09:00 | B22: 70 | C22: 70 | D22: 67 | E22: 87 | F22: 83 | G22: 40 | H22: 58 | I22: 68 | J22: =ROUND(I22*Config!C6/Config!C8/Config!C7,1) | K22: 13 | L22: =ROUND(K22-J22,1) | M22: =IF(L22>=3,"Comfortable",IF(L22>=1,"Good",IF(L22>=0,"Tight",IF(L22>=-2,"Under","Critical")))) | N22: S1
A23: 09:30 | B23: 60 | C23: 84 | D23: 80 | E23: 79 | F23: 77 | G23: 50 | H23: 57 | I23: 70 | J23: =ROUND(I23*Config!C6/Config!C8/Config!C7,1) | K23: 13 | L23: =ROUND(K23-J23,1) | M23: =IF(L23>=3,"Comfortable",IF(L23>=1,"Good",IF(L23>=0,"Tight",IF(L23>=-2,"Under","Critical")))) | N23: S1
A24: 10:00 | B24: 76 | C24: 79 | D24: 70 | E24: 83 | F24: 54 | G24: 51 | H24: 58 | I24: 67 | J24: =ROUND(I24*Config!C6/Config!C8/Config!C7,1) | K24: 13 | L24: =ROUND(K24-J24,1) | M24: =IF(L24>=3,"Comfortable",IF(L24>=1,"Good",IF(L24>=0,"Tight",IF(L24>=-2,"Under","Critical")))) | N24: S1
A25: 10:30 | B25: 56 | C25: 99 | D25: 66 | E25: 56 | F25: 52 | G25: 47 | H25: 52 | I25: 61 | J25: =ROUND(I25*Config!C6/Config!C8/Config!C7,1) | K25: 13 | L25: =ROUND(K25-J25,1) | M25: =IF(L25>=3,"Comfortable",IF(L25>=1,"Good",IF(L25>=0,"Tight",IF(L25>=-2,"Under","Critical")))) | N25: S1
A26: 11:00 | B26: 65 | C26: 63 | D26: 75 | E26: 83 | F26: 75 | G26: 49 | H26: 63 | I26: 68 | J26: =ROUND(I26*Config!C6/Config!C8/Config!C7,1) | K26: 13 | L26: =ROUND(K26-J26,1) | M26: =IF(L26>=3,"Comfortable",IF(L26>=1,"Good",IF(L26>=0,"Tight",IF(L26>=-2,"Under","Critical")))) | N26: S1
A27: 11:30 | B27: 75 | C27: 72 | D27: 80 | E27: 74 | F27: 75 | G27: 61 | H27: 55 | I27: 70 | J27: =ROUND(I27*Config!C6/Config!C8/Config!C7,1) | K27: 13 | L27: =ROUND(K27-J27,1) | M27: =IF(L27>=3,"Comfortable",IF(L27>=1,"Good",IF(L27>=0,"Tight",IF(L27>=-2,"Under","Critical")))) | N27: S1
A28: 12:00 | B28: 62 | C28: 65 | D28: 72 | E28: 58 | F28: 61 | G28: 52 | H28: 47 | I28: 60 | J28: =ROUND(I28*Config!C6/Config!C8/Config!C7,1) | K28: 13 | L28: =ROUND(K28-J28,1) | M28: =IF(L28>=3,"Comfortable",IF(L28>=1,"Good",IF(L28>=0,"Tight",IF(L28>=-2,"Under","Critical")))) | N28: S1
A29: 12:30 | B29: 67 | C29: 61 | D29: 82 | E29: 98 | F29: 77 | G29: 63 | H29: 53 | I29: 72 | J29: =ROUND(I29*Config!C6/Config!C8/Config!C7,1) | K29: 13 | L29: =ROUND(K29-J29,1) | M29: =IF(L29>=3,"Comfortable",IF(L29>=1,"Good",IF(L29>=0,"Tight",IF(L29>=-2,"Under","Critical")))) | N29: S1
A30: 13:00 | B30: 62 | C30: 64 | D30: 81 | E30: 84 | F30: 52 | G30: 47 | H30: 69 | I30: 66 | J30: =ROUND(I30*Config!C6/Config!C8/Config!C7,1) | K30: 13 | L30: =ROUND(K30-J30,1) | M30: =IF(L30>=3,"Comfortable",IF(L30>=1,"Good",IF(L30>=0,"Tight",IF(L30>=-2,"Under","Critical")))) | N30: S1
A31: 13:30 | B31: 74 | C31: 70 | D31: 63 | E31: 68 | F31: 63 | G31: 89 | H31: 52 | I31: 68 | J31: =ROUND(I31*Config!C6/Config!C8/Config!C7,1) | K31: 13 | L31: =ROUND(K31-J31,1) | M31: =IF(L31>=3,"Comfortable",IF(L31>=1,"Good",IF(L31>=0,"Tight",IF(L31>=-2,"Under","Critical")))) | N31: S1
A32: 14:00 | B32: 66 | C32: 74 | D32: 86 | E32: 81 | F32: 70 | G32: 50 | H32: 59 | I32: 69 | J32: =ROUND(I32*Config!C6/Config!C8/Config!C7,1) | K32: 13 | L32: =ROUND(K32-J32,1) | M32: =IF(L32>=3,"Comfortable",IF(L32>=1,"Good",IF(L32>=0,"Tight",IF(L32>=-2,"Under","Critical")))) | N32: S1
A33: 14:30 | B33: 63 | C33: 84 | D33: 74 | E33: 62 | F33: 79 | G33: 50 | H33: 69 | I33: 69 | J33: =ROUND(I33*Config!C6/Config!C8/Config!C7,1) | K33: 13 | L33: =ROUND(K33-J33,1) | M33: =IF(L33>=3,"Comfortable",IF(L33>=1,"Good",IF(L33>=0,"Tight",IF(L33>=-2,"Under","Critical")))) | N33: S1
A34: 15:00 | B34: 96 | C34: 112 | D34: 74 | E34: 85 | F34: 109 | G34: 44 | H34: 54 | I34: 82 | J34: =ROUND(I34*Config!C6/Config!C8/Config!C7,1) | K34: 23 | L34: =ROUND(K34-J34,1) | M34: =IF(L34>=3,"Comfortable",IF(L34>=1,"Good",IF(L34>=0,"Tight",IF(L34>=-2,"Under","Critical")))) | N34: S1+S2
A35: 15:30 | B35: 91 | C35: 102 | D35: 93 | E35: 104 | F35: 106 | G35: 67 | H35: 79 | I35: 92 | J35: =ROUND(I35*Config!C6/Config!C8/Config!C7,1) | K35: 23 | L35: =ROUND(K35-J35,1) | M35: =IF(L35>=3,"Comfortable",IF(L35>=1,"Good",IF(L35>=0,"Tight",IF(L35>=-2,"Under","Critical")))) | N35: S1+S2
A36: 16:00 | B36: 108 | C36: 96 | D36: 90 | E36: 89 | F36: 107 | G36: 79 | H36: 83 | I36: 93 | J36: =ROUND(I36*Config!C6/Config!C8/Config!C7,1) | K36: 10 | L36: =ROUND(K36-J36,1) | M36: =IF(L36>=3,"Comfortable",IF(L36>=1,"Good",IF(L36>=0,"Tight",IF(L36>=-2,"Under","Critical")))) | N36: S2
A37: 16:30 | B37: 97 | C37: 132 | D37: 102 | E37: 78 | F37: 81 | G37: 94 | H37: 55 | I37: 91 | J37: =ROUND(I37*Config!C6/Config!C8/Config!C7,1) | K37: 10 | L37: =ROUND(K37-J37,1) | M37: =IF(L37>=3,"Comfortable",IF(L37>=1,"Good",IF(L37>=0,"Tight",IF(L37>=-2,"Under","Critical")))) | N37: S2
A38: 17:00 | B38: 102 | C38: 107 | D38: 100 | E38: 113 | F38: 97 | G38: 80 | H38: 77 | I38: 97 | J38: =ROUND(I38*Config!C6/Config!C8/Config!C7,1) | K38: 10 | L38: =ROUND(K38-J38,1) | M38: =IF(L38>=3,"Comfortable",IF(L38>=1,"Good",IF(L38>=0,"Tight",IF(L38>=-2,"Under","Critical")))) | N38: S2
A39: 17:30 | B39: 106 | C39: 102 | D39: 108 | E39: 128 | F39: 103 | G39: 75 | H39: 101 | I39: 103 | J39: =ROUND(I39*Config!C6/Config!C8/Config!C7,1) | K39: 10 | L39: =ROUND(K39-J39,1) | M39: =IF(L39>=3,"Comfortable",IF(L39>=1,"Good",IF(L39>=0,"Tight",IF(L39>=-2,"Under","Critical")))) | N39: S2
A40: 18:00 | B40: 108 | C40: 120 | D40: 109 | E40: 135 | F40: 103 | G40: 110 | H40: 82 | I40: 110 | J40: =ROUND(I40*Config!C6/Config!C8/Config!C7,1) | K40: 20 | L40: =ROUND(K40-J40,1) | M40: =IF(L40>=3,"Comfortable",IF(L40>=1,"Good",IF(L40>=0,"Tight",IF(L40>=-2,"Under","Critical")))) | N40: S2+S3
A41: 18:30 | B41: 128 | C41: 118 | D41: 107 | E41: 117 | F41: 103 | G41: 97 | H41: 84 | I41: 108 | J41: =ROUND(I41*Config!C6/Config!C8/Config!C7,1) | K41: 20 | L41: =ROUND(K41-J41,1) | M41: =IF(L41>=3,"Comfortable",IF(L41>=1,"Good",IF(L41>=0,"Tight",IF(L41>=-2,"Under","Critical")))) | N41: S2+S3
...

Sheet Shrinkage Planner
A1: Shrinkage Planner | Edit AHT, Concurrency & Shrinkage in Config sheet | Auto-recalculates
A3: Slot | B3: Avg Chats | C3: Agents Needed | D3: Gross Online | E3: Unplanned Loss | F3: Net After Unplanned | G3: Planned Off | H3: Effective HC | I3: Gap | J3: Break Policy | K3: Status
A4: 00:00 | B4: 99 | C4: =ROUND(B4*Config!C6/Config!C8/Config!C7,1) | D4: 16 | E4: ="-"&TEXT(ROUND(D4*Config!C10,1),"0.0") | F4: =ROUND(D4*(1-Config!C10),1) | G4: 0 | H4: =ROUND(F4-G4,1) | I4: =ROUND(H4-C4,1) | J4: Block - peak slot | K4: =IF(I4>=4,"Comfortable",IF(I4>=1,"Good",IF(I4>=0,"Tight",IF(I4>=-2,"Under","Critical"))))
A5: 00:30 | B5: 96 | C5: =ROUND(B5*Config!C6/Config!C8/Config!C7,1) | D5: 16 | E5: ="-"&TEXT(ROUND(D5*Config!C10,1),"0.0") | F5: =ROUND(D5*(1-Config!C10),1) | G5: 0 | H5: =ROUND(F5-G5,1) | I5: =ROUND(H5-C5,1) | J5: Block - peak slot | K5: =IF(I5>=4,"Comfortable",IF(I5>=1,"Good",IF(I5>=0,"Tight",IF(I5>=-2,"Under","Critical"))))
A6: 01:00 | B6: 85 | C6: =ROUND(B6*Config!C6/Config!C8/Config!C7,1) | D6: 16 | E6: ="-"&TEXT(ROUND(D6*Config!C10,1),"0.0") | F6: =ROUND(D6*(1-Config!C10),1) | G6: -1 | H6: =ROUND(F6-G6,1) | I6: =ROUND(H6-C6,1) | J6: Max 1 agent on break | K6: =IF(I6>=4,"Comfortable",IF(I6>=1,"Good",IF(I6>=0,"Tight",IF(I6>=-2,"Under","Critical"))))
A7: 01:30 | B7: 85 | C7: =ROUND(B7*Config!C6/Config!C8/Config!C7,1) | D7: 16 | E7: ="-"&TEXT(ROUND(D7*Config!C10,1),"0.0") | F7: =ROUND(D7*(1-Config!C10),1) | G7: -1 | H7: =ROUND(F7-G7,1) | I7: =ROUND(H7-C7,1) | J7: Max 1 agent on break | K7: =IF(I7>=4,"Comfortable",IF(I7>=1,"Good",IF(I7>=0,"Tight",IF(I7>=-2,"Under","Critical"))))
A8: 02:00 | B8: 79 | C8: =ROUND(B8*Config!C6/Config!C8/Config!C7,1) | D8: 16 | E8: ="-"&TEXT(ROUND(D8*Config!C10,1),"0.0") | F8: =ROUND(D8*(1-Config!C10),1) | G8: -1 | H8: =ROUND(F8-G8,1) | I8: =ROUND(H8-C8,1) | J8: Max 1 agent on break | K8: =IF(I8>=4,"Comfortable",IF(I8>=1,"Good",IF(I8>=0,"Tight",IF(I8>=-2,"Under","Critical"))))
A9: 02:30 | B9: 78 | C9: =ROUND(B9*Config!C6/Config!C8/Config!C7,1) | D9: 16 | E9: ="-"&TEXT(ROUND(D9*Config!C10,1),"0.0") | F9: =ROUND(D9*(1-Config!C10),1) | G9: -1 | H9: =ROUND(F9-G9,1) | I9: =ROUND(H9-C9,1) | J9: Max 1 agent on break | K9: =IF(I9>=4,"Comfortable",IF(I9>=1,"Good",IF(I9>=0,"Tight",IF(I9>=-2,"Under","Critical"))))
A10: 03:00 | B10: 72 | C10: =ROUND(B10*Config!C6/Config!C8/Config!C7,1) | D10: 6 | E10: ="-"&TEXT(ROUND(D10*Config!C10,1),"0.0") | F10: =ROUND(D10*(1-Config!C10),1) | G10: -2 | H10: =ROUND(F10-G10,1) | I10: =ROUND(H10-C10,1) | J10: Safe - 2 agents on break | K10: =IF(I10>=4,"Comfortable",IF(I10>=1,"Good",IF(I10>=0,"Tight",IF(I10>=-2,"Under","Critical"))))
A11: 03:30 | B11: 79 | C11: =ROUND(B11*Config!C6/Config!C8/Config!C7,1) | D11: 6 | E11: ="-"&TEXT(ROUND(D11*Config!C10,1),"0.0") | F11: =ROUND(D11*(1-Config!C10),1) | G11: -1 | H11: =ROUND(F11-G11,1) | I11: =ROUND(H11-C11,1) | J11: Max 1 agent on break | K11: =IF(I11>=4,"Comfortable",IF(I11>=1,"Good",IF(I11>=0,"Tight",IF(I11>=-2,"Under","Critical"))))
A12: 04:00 | B12: 63 | C12: =ROUND(B12*Config!C6/Config!C8/Config!C7,1) | D12: 6 | E12: ="-"&TEXT(ROUND(D12*Config!C10,1),"0.0") | F12: =ROUND(D12*(1-Config!C10),1) | G12: -2 | H12: =ROUND(F12-G12,1) | I12: =ROUND(H12-C12,1) | J12: Safe - 2 agents on break | K12: =IF(I12>=4,"Comfortable",IF(I12>=1,"Good",IF(I12>=0,"Tight",IF(I12>=-2,"Under","Critical"))))
A13: 04:30 | B13: 63 | C13: =ROUND(B13*Config!C6/Config!C8/Config!C7,1) | D13: 6 | E13: ="-"&TEXT(ROUND(D13*Config!C10,1),"0.0") | F13: =ROUND(D13*(1-Config!C10),1) | G13: -2 | H13: =ROUND(F13-G13,1) | I13: =ROUND(H13-C13,1) | J13: Safe - 2 agents on break | K13: =IF(I13>=4,"Comfortable",IF(I13>=1,"Good",IF(I13>=0,"Tight",IF(I13>=-2,"Under","Critical"))))
A14: 05:00 | B14: 59 | C14: =ROUND(B14*Config!C6/Config!C8/Config!C7,1) | D14: 6 | E14: ="-"&TEXT(ROUND(D14*Config!C10,1),"0.0") | F14: =ROUND(D14*(1-Config!C10),1) | G14: -2 | H14: =ROUND(F14-G14,1) | I14: =ROUND(H14-C14,1) | J14: Safe - 2 agents on break | K14: =IF(I14>=4,"Comfortable",IF(I14>=1,"Good",IF(I14>=0,"Tight",IF(I14>=-2,"Under","Critical"))))
A15: 05:30 | B15: 64 | C15: =ROUND(B15*Config!C6/Config!C8/Config!C7,1) | D15: 6 | E15: ="-"&TEXT(ROUND(D15*Config!C10,1),"0.0") | F15: =ROUND(D15*(1-Config!C10),1) | G15: -2 | H15: =ROUND(F15-G15,1) | I15: =ROUND(H15-C15,1) | J15: Safe - 2 agents on break | K15: =IF(I15>=4,"Comfortable",IF(I15>=1,"Good",IF(I15>=0,"Tight",IF(I15>=-2,"Under","Critical"))))
A16: 06:00 | B16: 65 | C16: =ROUND(B16*Config!C6/Config!C8/Config!C7,1) | D16: 6 | E16: ="-"&TEXT(ROUND(D16*Config!C10,1),"0.0") | F16: =ROUND(D16*(1-Config!C10),1) | G16: -2 | H16: =ROUND(F16-G16,1) | I16: =ROUND(H16-C16,1) | J16: Safe - 2 agents on break | K16: =IF(I16>=4,"Comfortable",IF(I16>=1,"Good",IF(I16>=0,"Tight",IF(I16>=-2,"Under","Critical"))))
A17: 06:30 | B17: 74 | C17: =ROUND(B17*Config!C6/Config!C8/Config!C7,1) | D17: 6 | E17: ="-"&TEXT(ROUND(D17*Config!C10,1),"0.0") | F17: =ROUND(D17*(1-Config!C10),1) | G17: -1 | H17: =ROUND(F17-G17,1) | I17: =ROUND(H17-C17,1) | J17: Max 1 agent on break | K17: =IF(I17>=4,"Comfortable",IF(I17>=1,"Good",IF(I17>=0,"Tight",IF(I17>=-2,"Under","Critical"))))
A18: 07:00 | B18: 67 | C18: =ROUND(B18*Config!C6/Config!C8/Config!C7,1) | D18: 19 | E18: ="-"&TEXT(ROUND(D18*Config!C10,1),"0.0") | F18: =ROUND(D18*(1-Config!C10),1) | G18: -2 | H18: =ROUND(F18-G18,1) | I18: =ROUND(H18-C18,1) | J18: Safe - 2 agents on break | K18: =IF(I18>=4,"Comfortable",IF(I18>=1,"Good",IF(I18>=0,"Tight",IF(I18>=-2,"Under","Critical"))))
A19: 07:30 | B19: 72 | C19: =ROUND(B19*Config!C6/Config!C8/Config!C7,1) | D19: 19 | E19: ="-"&TEXT(ROUND(D19*Config!C10,1),"0.0") | F19: =ROUND(D19*(1-Config!C10),1) | G19: -2 | H19: =ROUND(F19-G19,1) | I19: =ROUND(H19-C19,1) | J19: Safe - 2 agents on break | K19: =IF(I19>=4,"Comfortable",IF(I19>=1,"Good",IF(I19>=0,"Tight",IF(I19>=-2,"Under","Critical"))))
A20: 08:00 | B20: 75 | C20: =ROUND(B20*Config!C6/Config!C8/Config!C7,1) | D20: 13 | E20: ="-"&TEXT(ROUND(D20*Config!C10,1),"0.0") | F20: =ROUND(D20*(1-Config!C10),1) | G20: -1 | H20: =ROUND(F20-G20,1) | I20: =ROUND(H20-C20,1) | J20: Max 1 agent on break | K20: =IF(I20>=4,"Comfortable",IF(I20>=1,"Good",IF(I20>=0,"Tight",IF(I20>=-2,"Under","Critical"))))
A21: 08:30 | B21: 69 | C21: =ROUND(B21*Config!C6/Config!C8/Config!C7,1) | D21: 13 | E21: ="-"&TEXT(ROUND(D21*Config!C10,1),"0.0") | F21: =ROUND(D21*(1-Config!C10),1) | G21: -2 | H21: =ROUND(F21-G21,1) | I21: =ROUND(H21-C21,1) | J21: Safe - 2 agents on break | K21: =IF(I21>=4,"Comfortable",IF(I21>=1,"Good",IF(I21>=0,"Tight",IF(I21>=-2,"Under","Critical"))))
A22: 09:00 | B22: 68 | C22: =ROUND(B22*Config!C6/Config!C8/Config!C7,1) | D22: 13 | E22: ="-"&TEXT(ROUND(D22*Config!C10,1),"0.0") | F22: =ROUND(D22*(1-Config!C10),1) | G22: -2 | H22: =ROUND(F22-G22,1) | I22: =ROUND(H22-C22,1) | J22: Safe - 2 agents on break | K22: =IF(I22>=4,"Comfortable",IF(I22>=1,"Good",IF(I22>=0,"Tight",IF(I22>=-2,"Under","Critical"))))
A23: 09:30 | B23: 70 | C23: =ROUND(B23*Config!C6/Config!C8/Config!C7,1) | D23: 13 | E23: ="-"&TEXT(ROUND(D23*Config!C10,1),"0.0") | F23: =ROUND(D23*(1-Config!C10),1) | G23: -2 | H23: =ROUND(F23-G23,1) | I23: =ROUND(H23-C23,1) | J23: Safe - 2 agents on break | K23: =IF(I23>=4,"Comfortable",IF(I23>=1,"Good",IF(I23>=0,"Tight",IF(I23>=-2,"Under","Critical"))))
A24: 10:00 | B24: 67 | C24: =ROUND(B24*Config!C6/Config!C8/Config!C7,1) | D24: 13 | E24: ="-"&TEXT(ROUND(D24*Config!C10,1),"0.0") | F24: =ROUND(D24*(1-Config!C10),1) | G24: -2 | H24: =ROUND(F24-G24,1) | I24: =ROUND(H24-C24,1) | J24: Safe - 2 agents on break | K24: =IF(I24>=4,"Comfortable",IF(I24>=1,"Good",IF(I24>=0,"Tight",IF(I24>=-2,"Under","Critical"))))
A25: 10:30 | B25: 61 | C25: =ROUND(B25*Config!C6/Config!C8/Config!C7,1) | D25: 13 | E25: ="-"&TEXT(ROUND(D25*Config!C10,1),"0.0") | F25: =ROUND(D25*(1-Config!C10),1) | G25: -2 | H25: =ROUND(F25-G25,1) | I25: =ROUND(H25-C25,1) | J25: Safe - 2 agents on break | K25: =IF(I25>=4,"Comfortable",IF(I25>=1,"Good",IF(I25>=0,"Tight",IF(I25>=-2,"Under","Critical"))))
A26: 11:00 | B26: 68 | C26: =ROUND(B26*Config!C6/Config!C8/Config!C7,1) | D26: 13 | E26: ="-"&TEXT(ROUND(D26*Config!C10,1),"0.0") | F26: =ROUND(D26*(1-Config!C10),1) | G26: -2 | H26: =ROUND(F26-G26,1) | I26: =ROUND(H26-C26,1) | J26: Safe - 2 agents on break | K26: =IF(I26>=4,"Comfortable",IF(I26>=1,"Good",IF(I26>=0,"Tight",IF(I26>=-2,"Under","Critical"))))
A27: 11:30 | B27: 70 | C27: =ROUND(B27*Config!C6/Config!C8/Config!C7,1) | D27: 13 | E27: ="-"&TEXT(ROUND(D27*Config!C10,1),"0.0") | F27: =ROUND(D27*(1-Config!C10),1) | G27: -2 | H27: =ROUND(F27-G27,1) | I27: =ROUND(H27-C27,1) | J27: Safe - 2 agents on break | K27: =IF(I27>=4,"Comfortable",IF(I27>=1,"Good",IF(I27>=0,"Tight",IF(I27>=-2,"Under","Critical"))))
A28: 12:00 | B28: 60 | C28: =ROUND(B28*Config!C6/Config!C8/Config!C7,1) | D28: 13 | E28: ="-"&TEXT(ROUND(D28*Config!C10,1),"0.0") | F28: =ROUND(D28*(1-Config!C10),1) | G28: -2 | H28: =ROUND(F28-G28,1) | I28: =ROUND(H28-C28,1) | J28: Safe - 2 agents on break | K28: =IF(I28>=4,"Comfortable",IF(I28>=1,"Good",IF(I28>=0,"Tight",IF(I28>=-2,"Under","Critical"))))
A29: 12:30 | B29: 72 | C29: =ROUND(B29*Config!C6/Config!C8/Config!C7,1) | D29: 13 | E29: ="-"&TEXT(ROUND(D29*Config!C10,1),"0.0") | F29: =ROUND(D29*(1-Config!C10),1) | G29: -2 | H29: =ROUND(F29-G29,1) | I29: =ROUND(H29-C29,1) | J29: Safe - 2 agents on break | K29: =IF(I29>=4,"Comfortable",IF(I29>=1,"Good",IF(I29>=0,"Tight",IF(I29>=-2,"Under","Critical"))))
A30: 13:00 | B30: 66 | C30: =ROUND(B30*Config!C6/Config!C8/Config!C7,1) | D30: 13 | E30: ="-"&TEXT(ROUND(D30*Config!C10,1),"0.0") | F30: =ROUND(D30*(1-Config!C10),1) | G30: -2 | H30: =ROUND(F30-G30,1) | I30: =ROUND(H30-C30,1) | J30: Safe - 2 agents on break | K30: =IF(I30>=4,"Comfortable",IF(I30>=1,"Good",IF(I30>=0,"Tight",IF(I30>=-2,"Under","Critical"))))
A31: 13:30 | B31: 68 | C31: =ROUND(B31*Config!C6/Config!C8/Config!C7,1) | D31: 13 | E31: ="-"&TEXT(ROUND(D31*Config!C10,1),"0.0") | F31: =ROUND(D31*(1-Config!C10),1) | G31: -2 | H31: =ROUND(F31-G31,1) | I31: =ROUND(H31-C31,1) | J31: Safe - 2 agents on break | K31: =IF(I31>=4,"Comfortable",IF(I31>=1,"Good",IF(I31>=0,"Tight",IF(I31>=-2,"Under","Critical"))))
A32: 14:00 | B32: 69 | C32: =ROUND(B32*Config!C6/Config!C8/Config!C7,1) | D32: 13 | E32: ="-"&TEXT(ROUND(D32*Config!C10,1),"0.0") | F32: =ROUND(D32*(1-Config!C10),1) | G32: -2 | H32: =ROUND(F32-G32,1) | I32: =ROUND(H32-C32,1) | J32: Safe - 2 agents on break | K32: =IF(I32>=4,"Comfortable",IF(I32>=1,"Good",IF(I32>=0,"Tight",IF(I32>=-2,"Under","Critical"))))
A33: 14:30 | B33: 69 | C33: =ROUND(B33*Config!C6/Config!C8/Config!C7,1) | D33: 13 | E33: ="-"&TEXT(ROUND(D33*Config!C10,1),"0.0") | F33: =ROUND(D33*(1-Config!C10),1) | G33: -2 | H33: =ROUND(F33-G33,1) | I33: =ROUND(H33-C33,1) | J33: Safe - 2 agents on break | K33: =IF(I33>=4,"Comfortable",IF(I33>=1,"Good",IF(I33>=0,"Tight",IF(I33>=-2,"Under","Critical"))))
A34: 15:00 | B34: 82 | C34: =ROUND(B34*Config!C6/Config!C8/Config!C7,1) | D34: 23 | E34: ="-"&TEXT(ROUND(D34*Config!C10,1),"0.0") | F34: =ROUND(D34*(1-Config!C10),1) | G34: -1 | H34: =ROUND(F34-G34,1) | I34: =ROUND(H34-C34,1) | J34: Max 1 agent on break | K34: =IF(I34>=4,"Comfortable",IF(I34>=1,"Good",IF(I34>=0,"Tight",IF(I34>=-2,"Under","Critical"))))
A35: 15:30 | B35: 92 | C35: =ROUND(B35*Config!C6/Config!C8/Config!C7,1) | D35: 23 | E35: ="-"&TEXT(ROUND(D35*Config!C10,1),"0.0") | F35: =ROUND(D35*(1-Config!C10),1) | G35: 0 | H35: =ROUND(F35-G35,1) | I35: =ROUND(H35-C35,1) | J35: Block - peak slot | K35: =IF(I35>=4,"Comfortable",IF(I35>=1,"Good",IF(I35>=0,"Tight",IF(I35>=-2,"Under","Critical"))))
A36: 16:00 | B36: 93 | C36: =ROUND(B36*Config!C6/Config!C8/Config!C7,1) | D36: 10 | E36: ="-"&TEXT(ROUND(D36*Config!C10,1),"0.0") | F36: =ROUND(D36*(1-Config!C10),1) | G36: 0 | H36: =ROUND(F36-G36,1) | I36: =ROUND(H36-C36,1) | J36: Block - peak slot | K36: =IF(I36>=4,"Comfortable",IF(I36>=1,"Good",IF(I36>=0,"Tight",IF(I36>=-2,"Under","Critical"))))
A37: 16:30 | B37: 91 | C37: =ROUND(B37*Config!C6/Config!C8/Config!C7,1) | D37: 10 | E37: ="-"&TEXT(ROUND(D37*Config!C10,1),"0.0") | F37: =ROUND(D37*(1-Config!C10),1) | G37: 0 | H37: =ROUND(F37-G37,1) | I37: =ROUND(H37-C37,1) | J37: Block - peak slot | K37: =IF(I37>=4,"Comfortable",IF(I37>=1,"Good",IF(I37>=0,"Tight",IF(I37>=-2,"Under","Critical"))))
A38: 17:00 | B38: 97 | C38: =ROUND(B38*Config!C6/Config!C8/Config!C7,1) | D38: 10 | E38: ="-"&TEXT(ROUND(D38*Config!C10,1),"0.0") | F38: =ROUND(D38*(1-Config!C10),1) | G38: 0 | H38: =ROUND(F38-G38,1) | I38: =ROUND(H38-C38,1) | J38: Block - peak slot | K38: =IF(I38>=4,"Comfortable",IF(I38>=1,"Good",IF(I38>=0,"Tight",IF(I38>=-2,"Under","Critical"))))
A39: 17:30 | B39: 103 | C39: =ROUND(B39*Config!C6/Config!C8/Config!C7,1) | D39: 10 | E39: ="-"&TEXT(ROUND(D39*Config!C10,1),"0.0") | F39: =ROUND(D39*(1-Config!C10),1) | G39: 0 | H39: =ROUND(F39-G39,1) | I39: =ROUND(H39-C39,1) | J39: Block - peak slot | K39: =IF(I39>=4,"Comfortable",IF(I39>=1,"Good",IF(I39>=0,"Tight",IF(I39>=-2,"Under","Critical"))))
A40: 18:00 | B40: 110 | C40: =ROUND(B40*Config!C6/Config!C8/Config!C7,1) | D40: 20 | E40: ="-"&TEXT(ROUND(D40*Config!C10,1),"0.0") | F40: =ROUND(D40*(1-Config!C10),1) | G40: 0 | H40: =ROUND(F40-G40,1) | I40: =ROUND(H40-C40,1) | J40: Block - peak slot | K40: =IF(I40>=4,"Comfortable",IF(I40>=1,"Good",IF(I40>=0,"Tight",IF(I40>=-2,"Under","Critical"))))
A41: 18:30 | B41: 108 | C41: =ROUND(B41*Config!C6/Config!C8/Config!C7,1) | D41: 20 | E41: ="-"&TEXT(ROUND(D41*Config!C10,1),"0.0") | F41: =ROUND(D41*(1-Config!C10),1) | G41: 0 | H41: =ROUND(F41-G41,1) | I41: =ROUND(H41-C41,1) | J41: Block - peak slot | K41: =IF(I41>=4,"Comfortable",IF(I41>=1,"Good",IF(I41>=0,"Tight",IF(I41>=-2,"Under","Critical"))))
...
